package JAVA_OOP_Language.ExceptionHandling;

import java.util.Random;

public class exceptions {
  public static void main(String[] args) {
        int a=0,b=0,c=0;

    
         Random r = new Random();

         for(int i=0; i<10; i++){
            try{
                b=r.nextInt();
                c=r.nextInt();
                a=12345/(b/c);

            } catch(ArithmeticException e){
                System.out.println("Division by zero ashtece");
                a=0;
            }

            System.out.println("a: "+a); // 0 for catch operation" and other values is showing because it didnt go through the exception handling its just the random values generated by r.nextint()
         }
    
}
    
}
